Workbook

Sheet BOM
A1: 🌱 AUTONOMOUS FARM ROVER — Bill of Materials (Phase 3)
A2: Target Budget: $100–$200 USD | Market: US (Amazon / AliExpress / Adafruit / SparkFun)
A3: # | B3: Subsystem | C3: Component / Part | D3: Model / Spec | E3: Qty | F3: Unit Price ($) | G3: Total ($) | H3: Priority | I3: Source | J3: Notes
A4: COMPUTE
A5: 1 | B5: Compute | C5: Single-Board Computer | D5: Raspberry Pi 4 Model B (2GB) | E5: 1 | F5: 45 | G5: =E5*F5 -> 45 | H5: MUST HAVE | I5: CanaKit / Amazon | J5: Brain of rover – runs Python, vision, navigation
A6: 2 | B6: Compute | C6: MicroSD Card | D6: SanDisk 32GB Class 10 | E6: 1 | F6: 8 | G6: =E6*F6 -> 8 | H6: MUST HAVE | I6: Amazon | J6: OS + data storage for Pi
A7: 3 | B7: Compute | C7: Microcontroller | D7: Arduino Nano (ATmega328P) | E7: 1 | F7: 5 | G7: =E7*F7 -> 5 | H7: MUST HAVE | I7: Amazon / AliExpress | J7: Reflex layer – sensors & motor control
A8: SENSORS
A9: 4 | B9: Soil Sensors | C9: Capacitive Soil Moisture Sensor | D9: Capacitive v1.2 (analog) | E9: 2 | F9: 2.5 | G9: =E9*F9 -> 5 | H9: MUST HAVE | I9: AliExpress | J9: More reliable than resistive; 2 for redundancy
A10: 5 | B10: Soil Sensors | C10: Waterproof Temp Sensor | D10: DS18B20 (1-Wire) | E10: 2 | F10: 2 | G10: =E10*F10 -> 4 | H10: MUST HAVE | I10: Amazon / AliExpress | J10: Soil temperature, 1-Wire protocol
A11: 6 | B11: Environment | C11: Temp/Humidity/Pressure | D11: BME280 (I2C breakout) | E11: 1 | F11: 5 | G11: =E11*F11 -> 5 | H11: MUST HAVE | I11: Adafruit / Amazon | J11: Air temp, humidity, altitude
A12: VISION
A13: 7 | B13: Vision | C13: Camera Module | D13: Raspberry Pi Camera Module v2 | E13: 1 | F13: 25 | G13: =E13*F13 -> 25 | H13: MUST HAVE | I13: Amazon / PiShop | J13: 8MP; native CSI interface to Pi
A14: 8 | B14: Vision | C14: Camera Flex Cable (extended) | D14: 50cm Pi Camera Ribbon Cable | E14: 1 | F14: 2 | G14: =E14*F14 -> 2 | H14: NICE TO HAVE | I14: Amazon | J14: Allows camera mast mounting
A15: NAVIGATION
A16: 9 | B16: Navigation | C16: GPS Module | D16: NEO-6M GPS Module (UART) | E16: 1 | F16: 7 | G16: =E16*F16 -> 7 | H16: MUST HAVE | I16: Amazon / AliExpress | J16: Waypoint navigation; ~2.5m accuracy
A17: 10 | B17: Navigation | C17: IMU (Accel + Gyro + Mag) | D17: MPU-6050 (I2C) | E17: 1 | F17: 3 | G17: =E17*F17 -> 3 | H17: MUST HAVE | I17: Amazon / AliExpress | J17: Heading + tilt detection
A18: 11 | B18: Navigation | C18: Ultrasonic Sensor | D18: HC-SR04 | E18: 2 | F18: 1.5 | G18: =E18*F18 -> 3 | H18: MUST HAVE | I18: Amazon | J18: Front + rear obstacle detection
A19: MOBILITY
A20: 12 | B20: Mobility | C20: 4WD Robot Chassis Kit | D20: 4WD Smart Car Chassis + DC motors | E20: 1 | F20: 18 | G20: =E20*F20 -> 18 | H20: MUST HAVE | I20: Amazon / AliExpress | J20: Includes motors, wheels, frame, screws
A21: 13 | B21: Mobility | C21: Motor Driver | D21: L298N Dual H-Bridge Module | E21: 1 | F21: 4 | G21: =E21*F21 -> 4 | H21: MUST HAVE | I21: Amazon | J21: Controls 4 DC motors (2 per channel)
A22: 14 | B22: Mobility | C22: Wheel Encoders | D22: LM393 Speed Sensor (slot type) | E22: 4 | F22: 1 | G22: =E22*F22 -> 4 | H22: NICE TO HAVE | I22: AliExpress | J22: Odometry for dead-reckoning nav
A23: POWER
A24: 15 | B24: Power | C24: LiPo Battery Pack | D24: 3S 5200mAh 11.1V LiPo | E24: 1 | F24: 22 | G24: =E24*F24 -> 22 | H24: MUST HAVE | I24: Amazon / HobbyKing | J24: Main power source; ~3–4hr runtime estimate
A25: 16 | B25: Power | C25: Buck Converter (5V) | D25: LM2596 Step-Down Module | E25: 2 | F25: 1.5 | G25: =E25*F25 -> 3 | H25: MUST HAVE | I25: Amazon / AliExpress | J25: 5V for Pi + Arduino
A26: 17 | B26: Power | C26: Buck Converter (3.3V) | D26: AMS1117 3.3V Module | E26: 1 | F26: 0.8 | G26: =E26*F26 -> 0.8 | H26: MUST HAVE | I26: AliExpress | J26: 3.3V for sensors
A27: 18 | B27: Power | C27: Power Switch | D27: Rocker Switch (20A rated) | E27: 1 | F27: 1.5 | G27: =E27*F27 -> 1.5 | H27: MUST HAVE | I27: Amazon | J27: Main kill switch
A28: 19 | B28: Power | C28: Inline Fuse Holder + Fuses | D28: 5A & 10A fuses | E28: 1 | F28: 2.5 | G28: =E28*F28 -> 2.5 | H28: MUST HAVE | I28: Amazon | J28: Safety – protects battery circuit
A29: COMMS & WIRING
A30: 20 | B30: Communication | C30: USB A to Mini-B Cable | D30: Pi ↔ Arduino Serial Link | E30: 1 | F30: 2 | G30: =E30*F30 -> 2 | H30: MUST HAVE | I30: Amazon | J30: Serial comms between Pi and Arduino
A31: 21 | B31: Wiring | C31: Jumper Wire Kit | D31: M-M / M-F / F-F 120pcs | E31: 1 | F31: 5 | G31: =E31*F31 -> 5 | H31: MUST HAVE | I31: Amazon | J31: Prototyping connections
A32: 22 | B32: Wiring | C32: Breadboard | D32: 400-tie Mini Breadboard | E32: 1 | F32: 2 | G32: =E32*F32 -> 2 | H32: MUST HAVE | I32: Amazon | J32: Sensor/circuit prototyping
A33: 23 | B33: Wiring | C33: PCB Prototype Board | D33: Double-sided 5x7cm | E33: 2 | F33: 1.5 | G33: =E33*F33 -> 3 | H33: NICE TO HAVE | I33: AliExpress | J33: For permanent sensor wiring
A34: 24 | B34: Wiring | C34: Heat Shrink Tubing Kit | D34: Assorted sizes | E34: 1 | F34: 3 | G34: =E34*F34 -> 3 | H34: NICE TO HAVE | I34: Amazon | J34: Wire insulation & weather protection
A35: ENCLOSURE & MISC
A36: 25 | B36: Enclosure | C36: Waterproof Project Box | D36: IP65 ABS Box ~200x120mm | E36: 1 | F36: 8 | G36: =E36*F36 -> 8 | H36: MUST HAVE | I36: Amazon | J36: Houses Pi, Arduino, power electronics
A37: 26 | B37: Misc | C37: M3 Screw/Standoff Kit | D37: M3 Brass Standoff Assortment | E37: 1 | F37: 6 | G37: =E37*F37 -> 6 | H37: MUST HAVE | I37: Amazon | J37: Mounting boards and components
A38: 27 | B38: Misc | C38: Cable Ties + Velcro Strips | D38: Assorted pack | E38: 1 | F38: 3 | G38: =E38*F38 -> 3 | H38: NICE TO HAVE | I38: Amazon | J38: Cable management
A40: TOTAL ESTIMATED COST | G40: =SUM(G5,G6,G7,G9,G10,G11,G13,G14,G16,G17,G18,G20,G21,G22,G24,G25,G26,G27,G28,G30,G31,G32,G33,G34,G36,G37,G38) -> 199.8
A41: MUST HAVE items only | G41: =SUMIF(H5:H39,"MUST HAVE",G5:G39) -> 184.8
...

Sheet Budget Summary
A1: 🌱 FARM ROVER — Budget Summary
A2: All values linked from BOM sheet — edit unit prices there
A4: Category | B4: Subtotal ($) | C4: % of Budget | D4: Notes
A5: Compute | B5: =BOM!G4+BOM!G5+BOM!G6 -> 53 | C5: =IFERROR(B5/B14,0) -> 0
A6: Sensors | B6: =BOM!G8+BOM!G9+BOM!G10 -> 9 | C6: =IFERROR(B6/B14,0) -> 0
A7: Vision | B7: =BOM!G12+BOM!G13 -> 25 | C7: =IFERROR(B7/B14,0) -> 0
A8: Navigation | B8: =BOM!G15+BOM!G16+BOM!G17 -> 10 | C8: =IFERROR(B8/B14,0) -> 0
A9: Mobility | B9: =BOM!G19+BOM!G20+BOM!G21 -> 22 | C9: =IFERROR(B9/B14,0) -> 0
A10: Power | B10: =BOM!G23+BOM!G24+BOM!G25+BOM!G26+BOM!G27 -> 27.3 | C10: =IFERROR(B10/B14,0) -> 0
A11: Comms & Wiring | B11: =BOM!G29+BOM!G30+BOM!G31+BOM!G32+BOM!G33 -> 12 | C11: =IFERROR(B11/B14,0) -> 0
A12: Enclosure & Misc | B12: =BOM!G35+BOM!G36+BOM!G37 -> 14 | C12: =IFERROR(B12/B14,0) -> 0
A13: GRAND TOTAL | B13: =SUM(B5:B12) -> 172.3 | C13: 100.0%
A15: BUDGET STATUS
A16: Target Budget | B16: $200.00
A17: Total Cost | B17: =B13 -> 172.3
A18: Remaining / Overage | B18: =200-B13 -> 27.7
A19: Status | B19: =IF(B13<=200,"✅ Within Budget","⚠️ Over Budget") -> ✅ Within Budget

Sheet Procurement Checklist
A1: 🛒 AUTONOMOUS FARM ROVER — Procurement Checklist
A3: ✓ | B3: Component | C3: Source | D3: Qty | E3: Est. Price ($) | F3: Status | G3: Link / Notes
A4: ☐ | B4: Raspberry Pi 4 (2GB) | C4: Amazon / CanaKit | D4: 1 | E4: 45 | F4: Not Ordered
A5: ☐ | B5: SanDisk 32GB MicroSD | C5: Amazon | D5: 1 | E5: 8 | F5: Not Ordered
A6: ☐ | B6: Arduino Nano | C6: Amazon / AliExpress | D6: 1 | E6: 5 | F6: Not Ordered
A7: ☐ | B7: Capacitive Moisture Sensor x2 | C7: AliExpress | D7: 2 | E7: 2.5 | F7: Not Ordered
A8: ☐ | B8: DS18B20 Temp Sensor x2 | C8: Amazon / AliExpress | D8: 2 | E8: 2 | F8: Not Ordered
A9: ☐ | B9: BME280 Module | C9: Adafruit / Amazon | D9: 1 | E9: 5 | F9: Not Ordered
A10: ☐ | B10: Pi Camera Module v2 | C10: Amazon / PiShop | D10: 1 | E10: 25 | F10: Not Ordered
A11: ☐ | B11: Camera Ribbon 50cm | C11: Amazon | D11: 1 | E11: 2 | F11: Not Ordered
A12: ☐ | B12: NEO-6M GPS Module | C12: Amazon / AliExpress | D12: 1 | E12: 7 | F12: Not Ordered
A13: ☐ | B13: MPU-6050 IMU | C13: Amazon / AliExpress | D13: 1 | E13: 3 | F13: Not Ordered
A14: ☐ | B14: HC-SR04 Ultrasonic x2 | C14: Amazon | D14: 2 | E14: 1.5 | F14: Not Ordered
A15: ☐ | B15: 4WD Chassis Kit | C15: Amazon / AliExpress | D15: 1 | E15: 18 | F15: Not Ordered
... A30: ☐ | B30: Cable Ties + Velcro | C30: Amazon | D30: 1 | E30: 3 | F30: Not Ordered
